<?xml version="1.0" ?>
<!-- =================================================================================== -->
<!-- |    This document was autogenerated by xacro from ./6dof_huboq_simple.xacro      | -->
<!-- |    EDITING THIS FILE BY HAND IS NOT RECOMMENDED                                 | -->
<!-- =================================================================================== -->
<robot name="6dof_huboq" xmlns:xacro="http://ros.org/wiki/xacro">
  <!-- Include materials -->
  <material name="Black">
    <color rgba="0.0 0.0 0.0 1.0"/>
  </material>
  <material name="Red">
    <color rgba="0.8 0.0 0.0 1.0"/>
  </material>
  <material name="White">
    <color rgba="1.0 1.0 1.0 1.0"/>
  </material>
  <!-- BOTTOM FIXED LINK 
This link is the base of the arm in which arm is placed 
-->
  <!-- ///////////////////////////////////////////////////////////////////////////////////////////////////////////////////// -->
  <joint name="bottom_joint" type="fixed">
    <origin rpy="0 0 0" xyz="0 0 0"/>
    <parent link="base_link"/>
    <child link="bottom_link"/>
  </joint>
  <link name="bottom_link">
    <visual>
      <origin rpy="0 0 0" xyz=" 0 0 -0.04"/>
      <geometry>
        <box size="1 1 0.02"/>
      </geometry>
      <material name="Brown"/>
    </visual>
    <collision>
      <origin rpy="0 0 0" xyz=" 0 0 -0.04"/>
      <geometry>
        <box size="1 1 0.02"/>
      </geometry>
    </collision>
    &gt;
  
  </link>
  <gazebo reference="bottom_link">
    <material>Gazebo/White</material>
  </gazebo>
  <!-- ///////////////////////////////////////////////////////////////////////////////////////////////////////////////////// -->
  <link name="base_link">
    <visual>
      <geometry>
        <box size="0.14 0.07 0.1"/>
      </geometry>
      <origin rpy="0 0 0" xyz="0 0 0.05"/>
      <material name="yellow">
        <color rgba="1 1 0 1"/>
      </material>
    </visual>
    <collision>
      <geometry>
        <box size="0.14 0.07 0.1"/>
      </geometry>
      <origin rpy="0 0 0" xyz="0 0 0.05"/>
    </collision>
    <inertial>
      <mass value="1"/>
      <inertia ixx="0.5" ixy="0.0" ixz="0.0" iyy="0.5" iyz="0.0" izz="0.5"/>
    </inertial>
  </link>
  <joint name="HR_joint" type="revolute">
    <parent link="base_link"/>
    <child link="HR_link"/>
    <origin xyz="0 0 0.1"/>
    <axis xyz="1 0 0"/>
    <limit effort="300" lower="-0.698131700798" upper="0.698131700798" velocity="0.1"/>
    <dynamics damping="50" friction="1"/>
  </joint>
  <link name="HR_link">
    <visual>
      <geometry>
        <cylinder length="0.13" radius="0.06"/>
      </geometry>
      <origin rpy="0 1.570795 0" xyz="0 0 0"/>
      <material name="blue">
        <color rgba="0 0 1 1"/>
      </material>
    </visual>
    <collision>
      <geometry>
        <cylinder length="0.13" radius="0.06"/>
      </geometry>
      <origin rpy="0 1.570795 0" xyz="0 0 0"/>
    </collision>
    <inertial>
      <mass value="1"/>
      <inertia ixx="0.5" ixy="0.0" ixz="0.0" iyy="0.5" iyz="0.0" izz="0.5"/>
    </inertial>
  </link>
  <joint name="HP_joint" type="revolute">
    <parent link="HR_link"/>
    <child link="HP_link"/>
    <origin xyz="0 0 0"/>
    <axis xyz="0 1 0"/>
    <limit effort="300" lower="-1.3962634016" upper="1.3962634016" velocity="0.1"/>
    <dynamics damping="50" friction="1"/>
  </joint>
  <link name="HP_link">
    <visual>
      <geometry>
        <box size="0.1 0.11 0.28"/>
      </geometry>
      <origin rpy="0 0 0" xyz="0 0 0.14"/>
      <material name="red">
        <color rgba="1 0 0 1"/>
      </material>
    </visual>
    <collision>
      <geometry>
        <box size="0.1 0.11 0.28"/>
      </geometry>
      <origin rpy="0 0 0" xyz="0 0 0.14"/>
    </collision>
    <inertial>
      <mass value="1"/>
      <inertia ixx="0.5" ixy="0.0" ixz="0.0" iyy="0.5" iyz="0.0" izz="0.5"/>
    </inertial>
  </link>
  <joint name="Knee_joint" type="revolute">
    <parent link="HP_link"/>
    <child link="Knee_link"/>
    <origin xyz="0 0 0.28"/>
    <axis xyz="0 1 0"/>
    <limit effort="300" lower="-2.79252680319" upper="1.3962634016" velocity="0.1"/>
    <dynamics damping="50" friction="1"/>
  </joint>
  <link name="Knee_link">
    <visual>
      <geometry>
        <box size="0.1 0.11 0.28"/>
      </geometry>
      <origin rpy="0 0 0" xyz="0 0 0.14"/>
      <material name="cyon">
        <color rgba="0 1 1 1"/>
      </material>
    </visual>
    <collision>
      <geometry>
        <box size="0.1 0.11 0.28"/>
      </geometry>
      <origin rpy="0 0 0" xyz="0 0 0.14"/>
    </collision>
    <inertial>
      <mass value="1"/>
      <inertia ixx="0.5" ixy="0.0" ixz="0.0" iyy="0.5" iyz="0.0" izz="0.5"/>
    </inertial>
  </link>
  <joint name="AP_joint" type="revolute">
    <parent link="Knee_link"/>
    <child link="AP_link"/>
    <origin xyz="0 0 0.28"/>
    <axis xyz="0 1 0"/>
    <limit effort="300" lower="-1.57079632679" upper="1.57079632679" velocity="0.1"/>
    <dynamics damping="50" friction="1"/>
  </joint>
  <link name="AP_link">
    <visual>
      <geometry>
        <cylinder length="0.12" radius="0.06"/>
      </geometry>
      <origin rpy="1.570795 0 0" xyz="0 0 0"/>
      <material name="Magenta">
        <color rgba="1 0 1 1"/>
      </material>
    </visual>
    <collision>
      <geometry>
        <cylinder length="0.12" radius="0.06"/>
      </geometry>
      <origin rpy="1.570795 0 0" xyz="0 0 0"/>
    </collision>
    <inertial>
      <mass value="1"/>
      <inertia ixx="0.5" ixy="0.0" ixz="0.0" iyy="0.5" iyz="0.0" izz="0.5"/>
    </inertial>
  </link>
  <joint name="AR_joint" type="revolute">
    <parent link="AP_link"/>
    <child link="AR_link"/>
    <origin xyz="0 0 0"/>
    <axis xyz="1 0 0"/>
    <limit effort="300" lower="-1.3962634016" upper="1.3962634016" velocity="0.1"/>
    <dynamics damping="50" friction="1"/>
  </joint>
  <link name="AR_link">
    <visual>
      <geometry>
        <box size="0.15 0.1 0.175"/>
      </geometry>
      <origin rpy="0 0 0" xyz="0 0 0.0875"/>
      <material name="orange">
        <color rgba="1 0.5 0 1"/>
      </material>
    </visual>
    <collision>
      <geometry>
        <box size="0.15 0.1 0.175"/>
      </geometry>
      <origin rpy="0 0 0" xyz="0 0 0.0875"/>
    </collision>
    <inertial>
      <mass value="1"/>
      <inertia ixx="0.5" ixy="0.0" ixz="0.0" iyy="0.5" iyz="0.0" izz="0.5"/>
    </inertial>
  </link>
  <joint name="AY_joint" type="revolute">
    <parent link="AR_link"/>
    <child link="AY_link"/>
    <origin xyz="0 0 0.175"/>
    <axis xyz="0 0 1"/>
    <limit effort="300" lower="-3.14" upper="3.14" velocity="0.1"/>
    <dynamics damping="50" friction="1"/>
  </joint>
  <link name="AY_link">
    <visual>
      <geometry>
        <cylinder length="0.15" radius="0.15"/>
      </geometry>
      <origin rpy="0 0 0" xyz="0 0 0"/>
      <material name="Gray">
        <color rgba="0.3 0.3 0.3 1"/>
      </material>
    </visual>
    <collision>
      <geometry>
        <cylinder length="0.15" radius="0.15"/>
      </geometry>
      <origin rpy="0 0 0" xyz="0 0 0"/>
    </collision>
    <inertial>
      <mass value="1"/>
      <inertia ixx="0.5" ixy="0.0" ixz="0.0" iyy="0.5" iyz="0.0" izz="0.5"/>
    </inertial>
  </link>
  <!-- ///////////////////////////////////////////////////////////////////////////////////////////////////////////////////// -->
  <!-- Transmissions for ROS Control -->
  <transmission name="tran1">
    <type>transmission_interface/SimpleTransmission</type>
    <joint name="HR_joint">
      <hardwareInterface>hardware_interface/PositionJointInterface</hardwareInterface>
    </joint>
    <actuator name="motor1">
      <hardwareInterface>hardware_interface/PositionJointInterface</hardwareInterface>
      <mechanicalReduction>1</mechanicalReduction>
    </actuator>
  </transmission>
  <transmission name="tran1">
    <type>transmission_interface/SimpleTransmission</type>
    <joint name="HP_joint">
      <hardwareInterface>hardware_interface/PositionJointInterface</hardwareInterface>
    </joint>
    <actuator name="motor1">
      <hardwareInterface>hardware_interface/PositionJointInterface</hardwareInterface>
      <mechanicalReduction>1</mechanicalReduction>
    </actuator>
  </transmission>
  <transmission name="tran1">
    <type>transmission_interface/SimpleTransmission</type>
    <joint name="Knee_joint">
      <hardwareInterface>hardware_interface/PositionJointInterface</hardwareInterface>
    </joint>
    <actuator name="motor1">
      <hardwareInterface>hardware_interface/PositionJointInterface</hardwareInterface>
      <mechanicalReduction>1</mechanicalReduction>
    </actuator>
  </transmission>
  <transmission name="tran1">
    <type>transmission_interface/SimpleTransmission</type>
    <joint name="AP_joint">
      <hardwareInterface>hardware_interface/PositionJointInterface</hardwareInterface>
    </joint>
    <actuator name="motor1">
      <hardwareInterface>hardware_interface/PositionJointInterface</hardwareInterface>
      <mechanicalReduction>1</mechanicalReduction>
    </actuator>
  </transmission>
  <transmission name="tran1">
    <type>transmission_interface/SimpleTransmission</type>
    <joint name="AR_joint">
      <hardwareInterface>hardware_interface/PositionJointInterface</hardwareInterface>
    </joint>
    <actuator name="motor1">
      <hardwareInterface>hardware_interface/PositionJointInterface</hardwareInterface>
      <mechanicalReduction>1</mechanicalReduction>
    </actuator>
  </transmission>
  <transmission name="tran1">
    <type>transmission_interface/SimpleTransmission</type>
    <joint name="AY_joint">
      <hardwareInterface>hardware_interface/PositionJointInterface</hardwareInterface>
    </joint>
    <actuator name="motor1">
      <hardwareInterface>hardware_interface/PositionJointInterface</hardwareInterface>
      <mechanicalReduction>1</mechanicalReduction>
    </actuator>
  </transmission>
  <!-- ros_control plugin -->
  <gazebo>
    <plugin filename="libgazebo_ros_control.so" name="gazebo_ros_control">
      <robotNamespace>/6dof_huboq</robotNamespace>
    </plugin>
  </gazebo>
</robot>

