<?xml version="1.0" encoding="utf-8"?>
<!-- =================================================================================== -->
<!-- |    This document was autogenerated by xacro from kitech_segway_stl.xacro        | -->
<!-- |    EDITING THIS FILE BY HAND IS NOT RECOMMENDED                                 | -->
<!-- =================================================================================== -->
<robot name="kitech_segway_type" xmlns:xacro="http://ros.org/wiki/xacro">
  <!-- BASE-FOOTPRINT -->
  <!-- base_footprint is a fictitious link(frame) that is on the ground right below base_link origin -->
  <link name="base_footprint">
    <inertial>
      <mass value="0.0001"/>
      <origin xyz="0 0 0"/>
      <inertia ixx="0.0001" ixy="0.0" ixz="0.0" iyy="0.0001" iyz="0.0" izz="0.0001"/>
    </inertial>
    <visual>
      <origin rpy="0 0 0" xyz="0 0 0"/>
      <geometry>
        <box size="0.001 0.001 0.001"/>
      </geometry>
    </visual>
  </link>
  <gazebo reference="base_footprint">
    <turnGravityOff>false</turnGravityOff>
  </gazebo>
  <joint name="base_footprint_joint" type="fixed">
    <origin rpy="0 0 0" xyz="0 0 0"/>
    <parent link="base_footprint"/>
    <child link="base_link"/>
  </joint>
  <link name="base_link">
    <visual>
      <geometry>
        <mesh filename="package://kitech_segway_urdf_pkg/mesh/stl_brep/Segway Type_rev3_body.stl" scale="0.001 0.001 0.001"/>
      </geometry>
      <origin rpy="1.570795 0 0" xyz="0 0 0.5"/>
    </visual>
    <collision>
      <geometry>
        <box size="2.2 0.7 0.8"/>
      </geometry>
      <origin rpy="1.570795 0 0" xyz="0 0 0.45"/>
    </collision>
  </link>
  <gazebo reference="base_link">
    <turnGravityOff>false</turnGravityOff>
  </gazebo>
  <link name="mp_left_wheel">
    <visual>
      <geometry>
        <mesh filename="package://kitech_segway_urdf_pkg/mesh/stl_brep/wheel_0.35.stl" scale="0.001 0.001 0.001"/>
      </geometry>
      <origin rpy="0 0 1.570795" xyz="0 0 0"/>
    </visual>
    <collision>
      <geometry>
        <cylinder length="0.14" radius="0.2"/>
      </geometry>
      <origin rpy="1.570795 0 0" xyz="0 0 0"/>
    </collision>
  </link>
  <joint name="mp_left_wheel_joint" type="continuous">
    <parent link="base_link"/>
    <child link="mp_left_wheel"/>
    <origin xyz="-0.06 0.33 0.2"/>
    <axis xyz="0 1 0"/>
  </joint>
  <link name="mp_right_wheel">
    <visual>
      <geometry>
        <mesh filename="package://kitech_segway_urdf_pkg/mesh/stl_brep/wheel_0.35.stl" scale="0.001 0.001 0.001"/>
      </geometry>
      <origin rpy="0 0 -1.570795" xyz="0 0 0"/>
    </visual>
    <collision>
      <geometry>
        <cylinder length="0.14" radius="0.2"/>
      </geometry>
      <origin rpy="-1.570795 0 0" xyz="0 0 0"/>
    </collision>
  </link>
  <joint name="mp_right_wheel_joint" type="continuous">
    <parent link="base_link"/>
    <child link="mp_right_wheel"/>
    <origin xyz="-0.06 -0.33 0.2"/>
    <axis xyz="0 1 0"/>
  </joint>
  <transmission name="tran1">
    <type>transmission_interface/SimpleTransmission</type>
    <joint name="mp_left_wheel_joint">
      <hardwareInterface>hardware_interface/PositionJointInterface</hardwareInterface>
    </joint>
    <actuator name="motor1">
      <hardwareInterface>hardware_interface/PositionJointInterface</hardwareInterface>
      <mechanicalReduction>1</mechanicalReduction>
    </actuator>
  </transmission>
  <transmission name="tran1">
    <type>transmission_interface/SimpleTransmission</type>
    <joint name="mp_right_wheel_joint">
      <hardwareInterface>hardware_interface/PositionJointInterface</hardwareInterface>
    </joint>
    <actuator name="motor1">
      <hardwareInterface>hardware_interface/PositionJointInterface</hardwareInterface>
      <mechanicalReduction>1</mechanicalReduction>
    </actuator>
  </transmission>
  <!-- ros_control plugin -->
  <gazebo>
    <plugin filename="libgazebo_ros_control.so" name="gazebo_ros_control">
      <robotNamespace>/kitech_segway_type</robotNamespace>
    </plugin>
  </gazebo>
</robot>

