<?xml version="1.0"?>
<robot xmlns:xacro="http://ros.org/wiki/xacro">

    <!-- body marcro definition -->
    <xacro:macro name="kitech_robot_wheel" params="name reflect rotate">

        <joint name="${name}_wheel_joint" type="continuous">
            <origin xyz="0.0 ${reflect*0.3} 0.20085" />
            <parent link="body" />
            <child link="${name}_wheel" />
            <axis xyz="0 1 0" />
        </joint>

        <link name="${name}_wheel">
            <inertial>
                <origin xyz="0.0 ${reflect*0.032021} 0.0" />
                <mass value="3.871" />
                <inertia ixx="0.056425" ixy="0.0" ixz="0.0"
                    iyy="0.094098" iyz="0.0"
                    izz="0.056425" />
            </inertial>
            <visual>
                <origin xyz="0.0 0.0 0.0" rpy="${rotate*PI} 0.0 0.0"/>
                <geometry>
                    <mesh filename="package://kitech_robots_description/mesh/for_VREP/Wheel.stl" scale="0.001 0.001 0.001"/>
                </geometry>
            </visual>
            <collision>
                <origin xyz="0.0 ${reflect*0.0265} 0.0" rpy="${PI/2} 0.0 0.0" />
                <geometry>
                    <cylinder length="0.153" radius="0.2005" />
                </geometry>
            </collision>
        </link>

	    <transmission name="${name}_trans">
	      <type>transmission_interface/SimpleTransmission</type> 
	      <joint name="${name}_wheel_joint">
            <hardwareInterface>hardware_interface/EffortJointInterface</hardwareInterface>
	      </joint>
	      <actuator name="${name}_motor">
            <hardwareInterface>hardware_interface/EffortJointInterface</hardwareInterface>
	        <mechanicalReduction>1</mechanicalReduction>
	      </actuator>
	    </transmission>

    </xacro:macro>

</robot>

