<?xml version="1.0" ?>
<!-- =================================================================================== -->
<!-- |    This document was autogenerated by xacro from kitech_robot.xacro             | -->
<!-- |    EDITING THIS FILE BY HAND IS NOT RECOMMENDED                                 | -->
<!-- =================================================================================== -->
<robot name="kitech_robot" xmlns:xacro="http://ros.org/wiki/xacro">
  <!-- ros_control plugin -->
  <gazebo>
    <plugin filename="libgazebo_ros_control.so" name="gazebo_ros_control">
      <robotNamespace>/kitech_robot</robotNamespace>
      <robotSimType>gazebo_ros_control/DefaultRobotHWSim</robotSimType>
      <controlPeriod>0.001</controlPeriod>
    </plugin>
  </gazebo>
  <link name="world"/>
  <joint name="fixed_to_world" type="fixed">
    <origin xyz="0 0 0"/>
    <parent link="world"/>
    <child link="base_footprint"/>
  </joint>
  <!-- BASE-FOOTPRINT -->
  <!-- base_footprint is a fictitious link(frame) that is on the ground right below body origin -->
  <link name="base_footprint">
    <inertial>
      <origin xyz="0 0 0"/>
      <mass value="0.0001"/>
      <inertia ixx="0.0001" ixy="0.0" ixz="0.0" iyy="0.0001" iyz="0.0" izz="0.0001"/>
    </inertial>
    <visual>
      <origin rpy="0 0 0" xyz="0 0 0"/>
      <geometry>
        <box size="0.001 0.001 0.001"/>
      </geometry>
    </visual>
  </link>
  <joint name="footprint_body" type="fixed">
    <origin rpy="0 0 0" xyz="0 0 1"/>
    <parent link="base_footprint"/>
    <child link="body"/>
  </joint>
  <link name="body">
    <inertial>
      <origin rpy="0 0 0" xyz="0.062594 0.0 0.457496"/>
      <mass value="1181"/>
      <inertia ixx="64.387768" ixy="-0.007626" ixz="-7.441046" iyy="461.852065" iyz="-0.011013" izz="480.676973"/>
    </inertial>
    <visual>
      <origin xyz="0.0 0.0 0.46585"/>
      <geometry>
        <mesh filename="package://kitech_robots_description/mesh/for_VREP/Body_with_wheel_plate.stl" scale="0.001 0.001 0.001"/>
      </geometry>
    </visual>
    <collision>
      <origin xyz="0.059 0.0 0.425"/>
      <geometry>
        <box size="2.27 0.83 0.702"/>
      </geometry>
    </collision>
  </link>
  <joint name="LF_HAA_joint" type="revolute">
    <origin xyz="0.816 0.17 0.37085"/>
    <parent link="body"/>
    <child link="LF_limb_0"/>
    <axis xyz="1 0 0"/>
    <limit effort="500" lower="-3.14159265359" upper="3.14159265359" velocity="20"/>
    <!-- <dynamics damping="0.2" friction="0.2"/> -->
  </joint>
  <link name="LF_limb_0">
    <inertial>
      <origin xyz="-0.218617 0.0 -0.000024"/>
      <mass value="11.381"/>
      <inertia ixx="0.027746" ixy="0.0" ixz="0.0" iyy="0.331276" iyz="0.0" izz="0.308905"/>
    </inertial>
    <visual>
      <origin rpy="0.0 0.0 0.0" xyz="0.0 0.0 0.0"/>
      <geometry>
        <mesh filename="package://kitech_robots_description/mesh/for_VREP/Limb_0.stl" scale="0.001 0.001 0.001"/>
      </geometry>
    </visual>
    <collision>
      <origin rpy="0.0 0.0 0.0" xyz="-0.215 0.0 0.0"/>
      <geometry>
        <box size="0.58 0.054 0.16"/>
      </geometry>
    </collision>
  </link>
  <joint name="LF_HFE_joint" type="revolute">
    <origin xyz="0.0 0.11 0.0"/>
    <parent link="LF_limb_0"/>
    <child link="LF_limb_1"/>
    <axis xyz="0 1 0"/>
    <limit effort="500" lower="-1.57079632679" upper="-0.0" velocity="20"/>
    <!-- <dynamics damping="0.2" friction="0.2"/> -->
  </joint>
  <link name="LF_limb_1">
    <inertial>
      <origin xyz="-0.146209 0.004659 0.007285"/>
      <mass value="24.551"/>
      <inertia ixx="0.096263" ixy="-0.00973" ixz="-0.013271" iyy="0.395041" iyz="0.00026" izz="0.42336"/>
    </inertial>
    <visual>
      <origin rpy="0.0 0.0 0.0" xyz="0.0 0.0 0.0"/>
      <geometry>
        <mesh filename="package://kitech_robots_description/mesh/for_VREP/Limb_1_left.stl" scale="0.001 0.001 0.001"/>
      </geometry>
    </visual>
    <collision>
      <origin rpy="0.0 0.0 0.0" xyz="-0.205 0.013 0.0125"/>
      <geometry>
        <box size="0.53 0.196 0.155"/>
      </geometry>
    </collision>
  </link>
  <joint name="LF_KFE_joint" type="revolute">
    <origin xyz="-0.45 0.0 -0.03"/>
    <parent link="LF_limb_1"/>
    <child link="LF_limb_2"/>
    <axis xyz="0 1 0"/>
    <limit effort="500" lower="0.0" upper="3.14159265359" velocity="20"/>
    <!-- <dynamics damping="0.2" friction="0.2"/> -->
  </joint>
  <link name="LF_limb_2">
    <inertial>
      <origin xyz="0.114799 -1.4e-05 -0.044794"/>
      <mass value="6.629"/>
      <inertia ixx="0.009829" ixy="0.0" ixz="0.012479" iyy="0.107571" iyz="0.0" izz="0.103829"/>
    </inertial>
    <visual>
      <origin rpy="0.0 0.0 0.0" xyz="0.0 0.0 0.0"/>
      <geometry>
        <mesh filename="package://kitech_robots_description/mesh/for_VREP/Limb_2.stl" scale="0.001 0.001 0.001"/>
      </geometry>
    </visual>
    <collision>
      <origin rpy="0.0 0.0 0.0" xyz="0.171323 0.0 -0.036283"/>
      <geometry>
        <box size="0.497 0.095 0.153"/>
      </geometry>
    </collision>
  </link>
  <joint name="LF_foot" type="fixed">
    <origin xyz="0.4187 0.0 -0.044234"/>
    <parent link="LF_limb_2"/>
    <child link="LF_foot"/>
  </joint>
  <link name="LF_foot">
    <inertial>
      <origin xyz="0.0442 2.8e-05 -0.012672"/>
      <mass value="0.2"/>
      <inertia ixx="0.000083" ixy="0.0" ixz="0.0" iyy="0.000146" iyz="0.0" izz="0.000131"/>
    </inertial>
    <visual>
      <origin rpy="0.0 0.0 0.0" xyz="0.0 0.0 0.0"/>
      <geometry>
        <mesh filename="package://kitech_robots_description/mesh/for_VREP/Foot.stl" scale="0.001 0.001 0.001"/>
      </geometry>
    </visual>
    <collision>
      <origin rpy="1.57079632679 0.0 0.0" xyz="0.05 0.0 -0.013252"/>
      <geometry>
        <cylinder length="0.05" radius="0.035"/>
      </geometry>
    </collision>
  </link>
  <transmission name="LF_HAA_trans">
    <type>transmission_interface/SimpleTransmission</type>
    <joint name="LF_HAA_joint">
      <hardwareInterface>hardware_interface/EffortJointInterface</hardwareInterface>
    </joint>
    <actuator name="LF_HAA_motor">
      <hardwareInterface>hardware_interface/EffortJointInterface</hardwareInterface>
      <mechanicalReduction>1</mechanicalReduction>
    </actuator>
  </transmission>
  <transmission name="LF_HFE_trans">
    <type>transmission_interface/SimpleTransmission</type>
    <joint name="LF_HFE_joint">
      <hardwareInterface>hardware_interface/EffortJointInterface</hardwareInterface>
    </joint>
    <actuator name="LF_HFE_motor">
      <hardwareInterface>hardware_interface/EffortJointInterface</hardwareInterface>
      <mechanicalReduction>1</mechanicalReduction>
    </actuator>
  </transmission>
  <transmission name="LF_KFE_trans">
    <type>transmission_interface/SimpleTransmission</type>
    <joint name="LF_KFE_joint">
      <hardwareInterface>hardware_interface/EffortJointInterface</hardwareInterface>
    </joint>
    <actuator name="LF_KFE_motor">
      <hardwareInterface>hardware_interface/EffortJointInterface</hardwareInterface>
      <mechanicalReduction>1</mechanicalReduction>
    </actuator>
  </transmission>
  <joint name="RF_HAA_joint" type="revolute">
    <origin xyz="0.816 -0.17 0.37085"/>
    <parent link="body"/>
    <child link="RF_limb_0"/>
    <axis xyz="1 0 0"/>
    <limit effort="500" lower="-3.14159265359" upper="3.14159265359" velocity="20"/>
    <!-- <dynamics damping="0.2" friction="0.2"/> -->
  </joint>
  <link name="RF_limb_0">
    <inertial>
      <origin xyz="-0.218617 0.0 -0.000024"/>
      <mass value="11.381"/>
      <inertia ixx="0.027746" ixy="0.0" ixz="0.0" iyy="0.331276" iyz="0.0" izz="0.308905"/>
    </inertial>
    <visual>
      <origin rpy="0.0 0.0 0.0" xyz="0.0 0.0 0.0"/>
      <geometry>
        <mesh filename="package://kitech_robots_description/mesh/for_VREP/Limb_0.stl" scale="0.001 0.001 0.001"/>
      </geometry>
    </visual>
    <collision>
      <origin rpy="0.0 0.0 0.0" xyz="-0.215 0.0 0.0"/>
      <geometry>
        <box size="0.58 0.054 0.16"/>
      </geometry>
    </collision>
  </link>
  <joint name="RF_HFE_joint" type="revolute">
    <origin xyz="0.0 -0.11 0.0"/>
    <parent link="RF_limb_0"/>
    <child link="RF_limb_1"/>
    <axis xyz="0 1 0"/>
    <limit effort="500" lower="-1.57079632679" upper="-0.0" velocity="20"/>
    <!-- <dynamics damping="0.2" friction="0.2"/> -->
  </joint>
  <link name="RF_limb_1">
    <inertial>
      <origin xyz="-0.146209 -0.004659 0.007285"/>
      <mass value="24.551"/>
      <inertia ixx="0.096263" ixy="0.00973" ixz="-0.013271" iyy="0.395041" iyz="-0.00026" izz="0.42336"/>
    </inertial>
    <visual>
      <origin rpy="0.0 0.0 0.0" xyz="0.0 0.0 0.0"/>
      <geometry>
        <mesh filename="package://kitech_robots_description/mesh/for_VREP/Limb_1_right.stl" scale="0.001 0.001 0.001"/>
      </geometry>
    </visual>
    <collision>
      <origin rpy="0.0 0.0 0.0" xyz="-0.205 -0.013 0.0125"/>
      <geometry>
        <box size="0.53 0.196 0.155"/>
      </geometry>
    </collision>
  </link>
  <joint name="RF_KFE_joint" type="revolute">
    <origin xyz="-0.45 0.0 -0.03"/>
    <parent link="RF_limb_1"/>
    <child link="RF_limb_2"/>
    <axis xyz="0 1 0"/>
    <limit effort="500" lower="0.0" upper="3.14159265359" velocity="20"/>
    <!-- <dynamics damping="0.2" friction="0.2"/> -->
  </joint>
  <link name="RF_limb_2">
    <inertial>
      <origin xyz="0.114799 1.4e-05 -0.044794"/>
      <mass value="6.629"/>
      <inertia ixx="0.009829" ixy="0.0" ixz="0.012479" iyy="0.107571" iyz="0.0" izz="0.103829"/>
    </inertial>
    <visual>
      <origin rpy="0.0 0.0 0.0" xyz="0.0 0.0 0.0"/>
      <geometry>
        <mesh filename="package://kitech_robots_description/mesh/for_VREP/Limb_2.stl" scale="0.001 0.001 0.001"/>
      </geometry>
    </visual>
    <collision>
      <origin rpy="0.0 0.0 0.0" xyz="0.171323 0.0 -0.036283"/>
      <geometry>
        <box size="0.497 0.095 0.153"/>
      </geometry>
    </collision>
  </link>
  <joint name="RF_foot" type="fixed">
    <origin xyz="0.4187 0.0 -0.044234"/>
    <parent link="RF_limb_2"/>
    <child link="RF_foot"/>
  </joint>
  <link name="RF_foot">
    <inertial>
      <origin xyz="0.0442 -2.8e-05 -0.012672"/>
      <mass value="0.2"/>
      <inertia ixx="0.000083" ixy="0.0" ixz="0.0" iyy="0.000146" iyz="0.0" izz="0.000131"/>
    </inertial>
    <visual>
      <origin rpy="0.0 0.0 0.0" xyz="0.0 0.0 0.0"/>
      <geometry>
        <mesh filename="package://kitech_robots_description/mesh/for_VREP/Foot.stl" scale="0.001 0.001 0.001"/>
      </geometry>
    </visual>
    <collision>
      <origin rpy="1.57079632679 0.0 0.0" xyz="0.05 0.0 -0.013252"/>
      <geometry>
        <cylinder length="0.05" radius="0.035"/>
      </geometry>
    </collision>
  </link>
  <transmission name="RF_HAA_trans">
    <type>transmission_interface/SimpleTransmission</type>
    <joint name="RF_HAA_joint">
      <hardwareInterface>hardware_interface/EffortJointInterface</hardwareInterface>
    </joint>
    <actuator name="RF_HAA_motor">
      <hardwareInterface>hardware_interface/EffortJointInterface</hardwareInterface>
      <mechanicalReduction>1</mechanicalReduction>
    </actuator>
  </transmission>
  <transmission name="RF_HFE_trans">
    <type>transmission_interface/SimpleTransmission</type>
    <joint name="RF_HFE_joint">
      <hardwareInterface>hardware_interface/EffortJointInterface</hardwareInterface>
    </joint>
    <actuator name="RF_HFE_motor">
      <hardwareInterface>hardware_interface/EffortJointInterface</hardwareInterface>
      <mechanicalReduction>1</mechanicalReduction>
    </actuator>
  </transmission>
  <transmission name="RF_KFE_trans">
    <type>transmission_interface/SimpleTransmission</type>
    <joint name="RF_KFE_joint">
      <hardwareInterface>hardware_interface/EffortJointInterface</hardwareInterface>
    </joint>
    <actuator name="RF_KFE_motor">
      <hardwareInterface>hardware_interface/EffortJointInterface</hardwareInterface>
      <mechanicalReduction>1</mechanicalReduction>
    </actuator>
  </transmission>
  <joint name="LH_HAA_joint" type="revolute">
    <origin xyz="-0.816 0.17 0.37085"/>
    <parent link="body"/>
    <child link="LH_limb_0"/>
    <axis xyz="1 0 0"/>
    <limit effort="500" lower="-3.14159265359" upper="3.14159265359" velocity="20"/>
    <!-- <dynamics damping="0.2" friction="0.2"/> -->
  </joint>
  <link name="LH_limb_0">
    <inertial>
      <origin xyz="0.218617 0.0 -0.000024"/>
      <mass value="11.381"/>
      <inertia ixx="0.027746" ixy="0.0" ixz="0.0" iyy="0.331276" iyz="0.0" izz="0.308905"/>
    </inertial>
    <visual>
      <origin rpy="0.0 3.14159265359 0.0" xyz="0.0 0.0 0.0"/>
      <geometry>
        <mesh filename="package://kitech_robots_description/mesh/for_VREP/Limb_0.stl" scale="0.001 0.001 0.001"/>
      </geometry>
    </visual>
    <collision>
      <origin rpy="0.0 0.0 0.0" xyz="0.215 0.0 0.0"/>
      <geometry>
        <box size="0.58 0.054 0.16"/>
      </geometry>
    </collision>
  </link>
  <joint name="LH_HFE_joint" type="revolute">
    <origin xyz="0.0 0.11 0.0"/>
    <parent link="LH_limb_0"/>
    <child link="LH_limb_1"/>
    <axis xyz="0 1 0"/>
    <limit effort="500" lower="-0.0" upper="1.57079632679" velocity="20"/>
    <!-- <dynamics damping="0.2" friction="0.2"/> -->
  </joint>
  <link name="LH_limb_1">
    <inertial>
      <origin xyz="0.146209 0.004659 0.007285"/>
      <mass value="24.551"/>
      <inertia ixx="0.096263" ixy="-0.00973" ixz="-0.013271" iyy="0.395041" iyz="0.00026" izz="0.42336"/>
    </inertial>
    <visual>
      <origin rpy="0.0 0.0 3.14159265359" xyz="0.0 0.0 0.0"/>
      <geometry>
        <mesh filename="package://kitech_robots_description/mesh/for_VREP/Limb_1_right.stl" scale="0.001 0.001 0.001"/>
      </geometry>
    </visual>
    <collision>
      <origin rpy="0.0 0.0 3.14159265359" xyz="0.205 0.013 0.0125"/>
      <geometry>
        <box size="0.53 0.196 0.155"/>
      </geometry>
    </collision>
  </link>
  <joint name="LH_KFE_joint" type="revolute">
    <origin xyz="0.45 0.0 -0.03"/>
    <parent link="LH_limb_1"/>
    <child link="LH_limb_2"/>
    <axis xyz="0 1 0"/>
    <limit effort="500" lower="-3.14159265359" upper="0.0" velocity="20"/>
    <!-- <dynamics damping="0.2" friction="0.2"/> -->
  </joint>
  <link name="LH_limb_2">
    <inertial>
      <origin xyz="-0.114799 -1.4e-05 -0.044794"/>
      <mass value="6.629"/>
      <inertia ixx="0.009829" ixy="0.0" ixz="0.012479" iyy="0.107571" iyz="0.0" izz="0.103829"/>
    </inertial>
    <visual>
      <origin rpy="0.0 0.0 3.14159265359" xyz="0.0 0.0 0.0"/>
      <geometry>
        <mesh filename="package://kitech_robots_description/mesh/for_VREP/Limb_2.stl" scale="0.001 0.001 0.001"/>
      </geometry>
    </visual>
    <collision>
      <origin rpy="0.0 0.0 3.14159265359" xyz="-0.171323 0.0 -0.036283"/>
      <geometry>
        <box size="0.497 0.095 0.153"/>
      </geometry>
    </collision>
  </link>
  <joint name="LH_foot" type="fixed">
    <origin xyz="-0.4187 0.0 -0.044234"/>
    <parent link="LH_limb_2"/>
    <child link="LH_foot"/>
  </joint>
  <link name="LH_foot">
    <inertial>
      <origin xyz="-0.0442 2.8e-05 -0.012672"/>
      <mass value="0.2"/>
      <inertia ixx="0.000083" ixy="0.0" ixz="0.0" iyy="0.000146" iyz="0.0" izz="0.000131"/>
    </inertial>
    <visual>
      <origin rpy="0.0 0.0 3.14159265359" xyz="0.0 0.0 0.0"/>
      <geometry>
        <mesh filename="package://kitech_robots_description/mesh/for_VREP/Foot.stl" scale="0.001 0.001 0.001"/>
      </geometry>
    </visual>
    <collision>
      <origin rpy="1.57079632679 0.0 3.14159265359" xyz="-0.05 0.0 -0.013252"/>
      <geometry>
        <cylinder length="0.05" radius="0.035"/>
      </geometry>
    </collision>
  </link>
  <transmission name="LH_HAA_trans">
    <type>transmission_interface/SimpleTransmission</type>
    <joint name="LH_HAA_joint">
      <hardwareInterface>hardware_interface/EffortJointInterface</hardwareInterface>
    </joint>
    <actuator name="LH_HAA_motor">
      <hardwareInterface>hardware_interface/EffortJointInterface</hardwareInterface>
      <mechanicalReduction>1</mechanicalReduction>
    </actuator>
  </transmission>
  <transmission name="LH_HFE_trans">
    <type>transmission_interface/SimpleTransmission</type>
    <joint name="LH_HFE_joint">
      <hardwareInterface>hardware_interface/EffortJointInterface</hardwareInterface>
    </joint>
    <actuator name="LH_HFE_motor">
      <hardwareInterface>hardware_interface/EffortJointInterface</hardwareInterface>
      <mechanicalReduction>1</mechanicalReduction>
    </actuator>
  </transmission>
  <transmission name="LH_KFE_trans">
    <type>transmission_interface/SimpleTransmission</type>
    <joint name="LH_KFE_joint">
      <hardwareInterface>hardware_interface/EffortJointInterface</hardwareInterface>
    </joint>
    <actuator name="LH_KFE_motor">
      <hardwareInterface>hardware_interface/EffortJointInterface</hardwareInterface>
      <mechanicalReduction>1</mechanicalReduction>
    </actuator>
  </transmission>
  <joint name="RH_HAA_joint" type="revolute">
    <origin xyz="-0.816 -0.17 0.37085"/>
    <parent link="body"/>
    <child link="RH_limb_0"/>
    <axis xyz="1 0 0"/>
    <limit effort="500" lower="-3.14159265359" upper="3.14159265359" velocity="20"/>
    <!-- <dynamics damping="0.2" friction="0.2"/> -->
  </joint>
  <link name="RH_limb_0">
    <inertial>
      <origin xyz="0.218617 0.0 -0.000024"/>
      <mass value="11.381"/>
      <inertia ixx="0.027746" ixy="0.0" ixz="0.0" iyy="0.331276" iyz="0.0" izz="0.308905"/>
    </inertial>
    <visual>
      <origin rpy="0.0 3.14159265359 0.0" xyz="0.0 0.0 0.0"/>
      <geometry>
        <mesh filename="package://kitech_robots_description/mesh/for_VREP/Limb_0.stl" scale="0.001 0.001 0.001"/>
      </geometry>
    </visual>
    <collision>
      <origin rpy="0.0 0.0 0.0" xyz="0.215 0.0 0.0"/>
      <geometry>
        <box size="0.58 0.054 0.16"/>
      </geometry>
    </collision>
  </link>
  <joint name="RH_HFE_joint" type="revolute">
    <origin xyz="0.0 -0.11 0.0"/>
    <parent link="RH_limb_0"/>
    <child link="RH_limb_1"/>
    <axis xyz="0 1 0"/>
    <limit effort="500" lower="-0.0" upper="1.57079632679" velocity="20"/>
    <!-- <dynamics damping="0.2" friction="0.2"/> -->
  </joint>
  <link name="RH_limb_1">
    <inertial>
      <origin xyz="0.146209 -0.004659 0.007285"/>
      <mass value="24.551"/>
      <inertia ixx="0.096263" ixy="0.00973" ixz="-0.013271" iyy="0.395041" iyz="-0.00026" izz="0.42336"/>
    </inertial>
    <visual>
      <origin rpy="0.0 0.0 3.14159265359" xyz="0.0 0.0 0.0"/>
      <geometry>
        <mesh filename="package://kitech_robots_description/mesh/for_VREP/Limb_1_left.stl" scale="0.001 0.001 0.001"/>
      </geometry>
    </visual>
    <collision>
      <origin rpy="0.0 0.0 3.14159265359" xyz="0.205 -0.013 0.0125"/>
      <geometry>
        <box size="0.53 0.196 0.155"/>
      </geometry>
    </collision>
  </link>
  <joint name="RH_KFE_joint" type="revolute">
    <origin xyz="0.45 0.0 -0.03"/>
    <parent link="RH_limb_1"/>
    <child link="RH_limb_2"/>
    <axis xyz="0 1 0"/>
    <limit effort="500" lower="-3.14159265359" upper="0.0" velocity="20"/>
    <!-- <dynamics damping="0.2" friction="0.2"/> -->
  </joint>
  <link name="RH_limb_2">
    <inertial>
      <origin xyz="-0.114799 1.4e-05 -0.044794"/>
      <mass value="6.629"/>
      <inertia ixx="0.009829" ixy="0.0" ixz="0.012479" iyy="0.107571" iyz="0.0" izz="0.103829"/>
    </inertial>
    <visual>
      <origin rpy="0.0 0.0 3.14159265359" xyz="0.0 0.0 0.0"/>
      <geometry>
        <mesh filename="package://kitech_robots_description/mesh/for_VREP/Limb_2.stl" scale="0.001 0.001 0.001"/>
      </geometry>
    </visual>
    <collision>
      <origin rpy="0.0 0.0 3.14159265359" xyz="-0.171323 0.0 -0.036283"/>
      <geometry>
        <box size="0.497 0.095 0.153"/>
      </geometry>
    </collision>
  </link>
  <joint name="RH_foot" type="fixed">
    <origin xyz="-0.4187 0.0 -0.044234"/>
    <parent link="RH_limb_2"/>
    <child link="RH_foot"/>
  </joint>
  <link name="RH_foot">
    <inertial>
      <origin xyz="-0.0442 -2.8e-05 -0.012672"/>
      <mass value="0.2"/>
      <inertia ixx="0.000083" ixy="0.0" ixz="0.0" iyy="0.000146" iyz="0.0" izz="0.000131"/>
    </inertial>
    <visual>
      <origin rpy="0.0 0.0 3.14159265359" xyz="0.0 0.0 0.0"/>
      <geometry>
        <mesh filename="package://kitech_robots_description/mesh/for_VREP/Foot.stl" scale="0.001 0.001 0.001"/>
      </geometry>
    </visual>
    <collision>
      <origin rpy="1.57079632679 0.0 3.14159265359" xyz="-0.05 0.0 -0.013252"/>
      <geometry>
        <cylinder length="0.05" radius="0.035"/>
      </geometry>
    </collision>
  </link>
  <transmission name="RH_HAA_trans">
    <type>transmission_interface/SimpleTransmission</type>
    <joint name="RH_HAA_joint">
      <hardwareInterface>hardware_interface/EffortJointInterface</hardwareInterface>
    </joint>
    <actuator name="RH_HAA_motor">
      <hardwareInterface>hardware_interface/EffortJointInterface</hardwareInterface>
      <mechanicalReduction>1</mechanicalReduction>
    </actuator>
  </transmission>
  <transmission name="RH_HFE_trans">
    <type>transmission_interface/SimpleTransmission</type>
    <joint name="RH_HFE_joint">
      <hardwareInterface>hardware_interface/EffortJointInterface</hardwareInterface>
    </joint>
    <actuator name="RH_HFE_motor">
      <hardwareInterface>hardware_interface/EffortJointInterface</hardwareInterface>
      <mechanicalReduction>1</mechanicalReduction>
    </actuator>
  </transmission>
  <transmission name="RH_KFE_trans">
    <type>transmission_interface/SimpleTransmission</type>
    <joint name="RH_KFE_joint">
      <hardwareInterface>hardware_interface/EffortJointInterface</hardwareInterface>
    </joint>
    <actuator name="RH_KFE_motor">
      <hardwareInterface>hardware_interface/EffortJointInterface</hardwareInterface>
      <mechanicalReduction>1</mechanicalReduction>
    </actuator>
  </transmission>
  <joint name="left_wheel_joint" type="continuous">
    <origin xyz="0.0 0.3 0.20085"/>
    <parent link="body"/>
    <child link="left_wheel"/>
    <axis xyz="0 1 0"/>
  </joint>
  <link name="left_wheel">
    <inertial>
      <origin xyz="0.0 0.032021 0.0"/>
      <mass value="3.871"/>
      <inertia ixx="0.056425" ixy="0.0" ixz="0.0" iyy="0.094098" iyz="0.0" izz="0.056425"/>
    </inertial>
    <visual>
      <origin rpy="0.0 0.0 0.0" xyz="0.0 0.0 0.0"/>
      <geometry>
        <mesh filename="package://kitech_robots_description/mesh/for_VREP/Wheel.stl" scale="0.001 0.001 0.001"/>
      </geometry>
    </visual>
    <collision>
      <origin rpy="1.57079632679 0.0 0.0" xyz="0.0 0.0265 0.0"/>
      <geometry>
        <cylinder length="0.153" radius="0.2005"/>
      </geometry>
    </collision>
  </link>
  <transmission name="left_trans">
    <type>transmission_interface/SimpleTransmission</type>
    <joint name="left_wheel_joint">
      <hardwareInterface>hardware_interface/EffortJointInterface</hardwareInterface>
    </joint>
    <actuator name="left_motor">
      <hardwareInterface>hardware_interface/EffortJointInterface</hardwareInterface>
      <mechanicalReduction>1</mechanicalReduction>
    </actuator>
  </transmission>
  <joint name="right_wheel_joint" type="continuous">
    <origin xyz="0.0 -0.3 0.20085"/>
    <parent link="body"/>
    <child link="right_wheel"/>
    <axis xyz="0 1 0"/>
  </joint>
  <link name="right_wheel">
    <inertial>
      <origin xyz="0.0 -0.032021 0.0"/>
      <mass value="3.871"/>
      <inertia ixx="0.056425" ixy="0.0" ixz="0.0" iyy="0.094098" iyz="0.0" izz="0.056425"/>
    </inertial>
    <visual>
      <origin rpy="3.14159265359 0.0 0.0" xyz="0.0 0.0 0.0"/>
      <geometry>
        <mesh filename="package://kitech_robots_description/mesh/for_VREP/Wheel.stl" scale="0.001 0.001 0.001"/>
      </geometry>
    </visual>
    <collision>
      <origin rpy="1.57079632679 0.0 0.0" xyz="0.0 -0.0265 0.0"/>
      <geometry>
        <cylinder length="0.153" radius="0.2005"/>
      </geometry>
    </collision>
  </link>
  <transmission name="right_trans">
    <type>transmission_interface/SimpleTransmission</type>
    <joint name="right_wheel_joint">
      <hardwareInterface>hardware_interface/EffortJointInterface</hardwareInterface>
    </joint>
    <actuator name="right_motor">
      <hardwareInterface>hardware_interface/EffortJointInterface</hardwareInterface>
      <mechanicalReduction>1</mechanicalReduction>
    </actuator>
  </transmission>
</robot>

